Workbook

Sheet Tracker
A1: AI PHOTO TRACKER
A2: 📊 New: | B2: =COUNTIF(L5:L356,"New") -> 63 | E2: In process: | F2: =COUNTIF(L5:L356,"In process") -> 1 | I2: QC: | J2: =COUNTIF(L5:L356,"QC") -> 7 | L2: Approved: | M2: =COUNTIF(L5:L356,"Approved") -> 126 | N2: Denied: | O2: =COUNTIF(L5:L356,"Denied") -> 1
A3: 🔗 ARES | C3: 🔗 NanoBanana | G3: 🔗 Canva | J3: 🔗 Tutorial | L3: 🔗 Weekly call
A4: Acco ID | B4: Summer → winter | C4: Improve lighting | D4: Improve ambiance | E4: Replace sky | F4: Make beds | G4: Remove object | H4: Improve summer | I4: Count | J4: Assigned to | K4: Date assigned | L4: Status | M4: Priority | N4: Date completed | O4: Notes QC | P4: Request date | Q4: Rental expert
A5: AT.6364.53 | B5: 3, 6, 7 | I5: 3 | J5: Jill | K5: 46097 | L5: Approved | M5: High | N5: 46101 | P5: 46097 | Q5: Georg Stiegler
A6: AT.6370.09 | B6: 3, 2, 5 | I6: 3 | J6: Jill | K6: 46097 | L6: Approved | M6: High | N6: 46101 | P6: 46097 | Q6: Daniel Hell
A7: AT.9971.14 | B7: 62, 66, 64 | I7: 3 | J7: Jill | K7: 46097 | L7: Approved | M7: High | N7: 46106 | O7: Vervormingen en AI errors | P7: 46097 | Q7: Daniel Hell
A8: AT.6336.01 | B8: 52, 53, 55 | I8: 3 | J8: Jill | K8: 46097 | L8: Approved | M8: High | N8: 46108 | O8: Bij foto 68 en 69 is de tekst op het VfY-bord vervormd. | P8: 46097 | Q8: Georg Stiegler
A9: AT.8953.10 | B9: 74, 85 | I9: 1 | J9: Jill | K9: 46097 | L9: Approved | M9: High | N9: 46112 | P9: 46097 | Q9: Ilse Heijnen
A10: AT.8953.47 | B10: 2, 24, 31 | I10: 1 | J10: Jill | K10: 46097 | L10: Approved | M10: High | N10: 46112 | P10: 46097 | Q10: Ilse Heijnen
A11: NL.2159.02 | H11: 34, 39, 36, 52, 55, 35 | I11: {=SUMPRODUCT((B11:H11<>"")*1+(LEN(B11:H11)-LEN(SUBSTITUTE(B11:H11,",",""))))} -> 6 | J11: Jill | K11: 46107 | L11: Approved | M11: High | N11: 46112 | P11: 46107 | Q11: Ilse Heijnen
A12: NL.2159.01 | H12: 104, 107, 108, 109, 41, 79, 60, 78, 77 | I12: {=SUMPRODUCT((B12:H12<>"")*1+(LEN(B12:H12)-LEN(SUBSTITUTE(B12:H12,",",""))))} -> 9 | J12: Jill | K12: 46107 | L12: Approved | M12: High | N12: 46112 | O12: Terrastafel sfeervoller aankleden volgende x | P12: 46107 | Q12: Ilse Heijnen
A13: AT.5531.03 | B13: 55, 48, 49, 50, 51, 52, 54, 56 | G13: 48, 49, 50, 51, 54 | I13: {=SUMPRODUCT((B13:H13<>"")*1+(LEN(B13:H13)-LEN(SUBSTITUTE(B13:H13,",",""))))} -> 13 | J13: Jill | K13: 46115 | L13: Approved | M13: High | N13: 46127 | O13: Bij foto 58 zijn 2 schoorstenen toegevoegd die ik op het origineel niet zie | P13: 46115 | Q13: Ilse Heijnen
A14: AT.9542.15 | H14: 1, 52, 62 | I14: {=SUMPRODUCT((B14:H14<>"")*1+(LEN(B14:H14)-LEN(SUBSTITUTE(B14:H14,",",""))))} -> 3 | J14: Jill | K14: 46121 | L14: Approved | M14: High | N14: 46127 | O14: Foto 3 oogt te kunstmatig + er zijn dingen toegevoegd die er niet zijn (blik naar binnen bijv. - in het origineel zijn de deuren gesloten). | P14: 46121 | Q14: Carl-Peter Echtermeijer
A15: AT.9542.16 | H15: 51, 52, 41 | I15: {=SUMPRODUCT((B15:H15<>"")*1+(LEN(B15:H15)-LEN(SUBSTITUTE(B15:H15,",",""))))} -> 3 | J15: Jill | K15: 46121 | L15: Approved | M15: High | N15: 46127 | O15: Kun je foto 52 nog eens proberen, en in je prompt ook specifiek een omschrijving van een huisnummerbord verwerken? | P15: 46121 | Q15: Carl-Peter Echtermeijer
A16: AT.9542.181 | H16: 58, 60, 78 | I16: {=SUMPRODUCT((B16:H16<>"")*1+(LEN(B16:H16)-LEN(SUBSTITUTE(B16:H16,",",""))))} -> 3 | J16: Jill | K16: 46121 | L16: Approved | M16: High | N16: 46127 | O16: Kun je foto 58 nog eens proberen, en in je prompt ook specifiek een omschrijving van een huisnummerbord verwerken? | P16: 46121 | Q16: Carl-Peter Echtermeijer
A17: AT.9542.03 | H17: 43, 58, 59 | I17: {=SUMPRODUCT((B17:H17<>"")*1+(LEN(B17:H17)-LEN(SUBSTITUTE(B17:H17,",",""))))} -> 3 | J17: Jill | K17: 46121 | L17: Approved | M17: High | N17: 46127 | P17: 46121 | Q17: Carl-Peter Echtermeijer
A18: AT.9542.211 | H18: 50, 29 | I18: {=SUMPRODUCT((B18:H18<>"")*1+(LEN(B18:H18)-LEN(SUBSTITUTE(B18:H18,",",""))))} -> 2 | J18: Jill | K18: 46121 | L18: Approved | M18: High | N18: 46127 | P18: 46121 | Q18: Carl-Peter Echtermeijer
A19: AT.9542.02 | H19: 2, 70 | I19: {=SUMPRODUCT((B19:H19<>"")*1+(LEN(B19:H19)-LEN(SUBSTITUTE(B19:H19,",",""))))} -> 2 | J19: Jill | K19: 46121 | L19: Approved | M19: High | N19: 46127 | P19: 46121 | Q19: Carl-Peter Echtermeijer
A20: AT.9542.05 | H20: 43, 41, 70 | I20: {=SUMPRODUCT((B20:H20<>"")*1+(LEN(B20:H20)-LEN(SUBSTITUTE(B20:H20,",",""))))} -> 3 | J20: Jill | K20: 46121 | L20: Approved | M20: High | N20: 46125 | P20: 46121 | Q20: Carl-Peter Echtermeijer
A21: AT.9542.06 | H21: 69, 67 | I21: {=SUMPRODUCT((B21:H21<>"")*1+(LEN(B21:H21)-LEN(SUBSTITUTE(B21:H21,",",""))))} -> 2 | J21: Jill | K21: 46121 | L21: Approved | M21: High | N21: 46125 | P21: 46121 | Q21: Carl-Peter Echtermeijer
A22: AT.9542.08 | H22: 52, 49 | I22: {=SUMPRODUCT((B22:H22<>"")*1+(LEN(B22:H22)-LEN(SUBSTITUTE(B22:H22,",",""))))} -> 2 | J22: Jill | K22: 46121 | L22: Approved | M22: High | N22: 46125 | P22: 46121 | Q22: Carl-Peter Echtermeijer
A23: AT.9542.10 | H23: 67, 65 | I23: {=SUMPRODUCT((B23:H23<>"")*1+(LEN(B23:H23)-LEN(SUBSTITUTE(B23:H23,",",""))))} -> 2 | J23: Jill | K23: 46121 | L23: Approved | M23: High | N23: 46125 | P23: 46121 | Q23: Carl-Peter Echtermeijer
A24: AT.9542.11 | H24: 72, 62 | I24: {=SUMPRODUCT((B24:H24<>"")*1+(LEN(B24:H24)-LEN(SUBSTITUTE(B24:H24,",",""))))} -> 2 | J24: Jill | K24: 46121 | L24: Approved | M24: High | N24: 46125 | P24: 46121 | Q24: Carl-Peter Echtermeijer
A25: AT.9542.12 | H25: 69 | I25: {=SUMPRODUCT((B25:H25<>"")*1+(LEN(B25:H25)-LEN(SUBSTITUTE(B25:H25,",",""))))} -> 1 | J25: Jill | K25: 46121 | L25: Approved | M25: High | N25: 46125 | P25: 46121 | Q25: Carl-Peter Echtermeijer
A26: AT.9542.14 | H26: 1, 52 | I26: {=SUMPRODUCT((B26:H26<>"")*1+(LEN(B26:H26)-LEN(SUBSTITUTE(B26:H26,",",""))))} -> 2 | J26: Jill | K26: 46121 | L26: Approved | M26: High | N26: 46125 | O26: Misschien groene blaadjes toevoegen. | P26: 46121 | Q26: Carl-Peter Echtermeijer
A27: AT.9542.201 | H27: 43, 57 | I27: {=SUMPRODUCT((B27:H27<>"")*1+(LEN(B27:H27)-LEN(SUBSTITUTE(B27:H27,",",""))))} -> 2 | J27: Jill | K27: 46121 | L27: Approved | M27: High | N27: 46127 | P27: 46121 | Q27: Carl-Peter Echtermeijer
A28: AT.9542.202 | H28: 41, 54 | I28: {=SUMPRODUCT((B28:H28<>"")*1+(LEN(B28:H28)-LEN(SUBSTITUTE(B28:H28,",",""))))} -> 2 | J28: Jill | K28: 46121 | L28: Approved | M28: High | N28: 46127 | P28: 46121 | Q28: Carl-Peter Echtermeijer
A29: AT.9542.223 | H29: 40 | I29: {=SUMPRODUCT((B29:H29<>"")*1+(LEN(B29:H29)-LEN(SUBSTITUTE(B29:H29,",",""))))} -> 1 | J29: Jill | K29: 46121 | L29: Approved | M29: High | N29: 46127 | P29: 46121 | Q29: Carl-Peter Echtermeijer
A30: AT.9542.241 | H30: 39, 52 | I30: {=SUMPRODUCT((B30:H30<>"")*1+(LEN(B30:H30)-LEN(SUBSTITUTE(B30:H30,",",""))))} -> 2 | J30: Jill | K30: 46121 | L30: Approved | M30: High | N30: 46127 | P30: 46121 | Q30: Carl-Peter Echtermeijer
A31: AT.9542.242 | H31: 34, 70 | I31: {=SUMPRODUCT((B31:H31<>"")*1+(LEN(B31:H31)-LEN(SUBSTITUTE(B31:H31,",",""))))} -> 2 | J31: Jill | K31: 46121 | L31: Approved | M31: High | N31: 46127 | P31: 46121 | Q31: Carl-Peter Echtermeijer
A32: NL.5094.02 | C32: 6, 7 | D32: 3, 4, 5, 8, 9, 12, 17, 18 | F32: 3, 4, 5 | G32: 3, 12, 17, 25 | I32: {=SUMPRODUCT((B32:H32<>"")*1+(LEN(B32:H32)-LEN(SUBSTITUTE(B32:H32,",",""))))} -> 17 | J32: Wouter | K32: 46122 | L32: Approved | M32: High | N32: 46122 | O32: 3: 2 eenpersoonsbedden aan elkaar, nachtkastje+lamp beide zijden, rolgordijn raam, kast rechts weg · 4/5: idem maar zonder kast verwijderen · 6: badkamer lichter/mooier maken · 7: idem badkamer + opstapkrukje voor het bad · 8: muur waar 4p eettafel komt · 9: TV-muur, rechts bank+tafeltjes, links 2 stoelen · 12: rechts 4p eettafel, links TV aan muur naast deur, bank+salontafel+2 stoelen, vloer blijft grijs, draai plafondlamp weg · 17: kapotte kast → glans wit zoals rest, cups koffiemachine+waterkoker erop · 18: eetmeubilair op terras, zit-loungebank, terras helemaal schoonmaken, klein voorkorfje, evt 2 ligstoelen op gras, schutting hoek naast schuur tot huis (privacy) · 25: geen mensen in zwembad | P32: 46121 | Q32: Mark van Bruggen
A33: NL.5171.12 | D33: 1, 2, 3, 4, 5, 6, 7, 8, 9, 10, 11, 12, 13, 14 | I33: {=SUMPRODUCT((B33:H33<>"")*1+(LEN(B33:H33)-LEN(SUBSTITUTE(B33:H33,",",""))))} -> 14 | J33: Wouter | K33: 46122 | L33: Approved | M33: High | N33: 46122 | O33: Woning in aanbouw; verwijder bouwmateriaal, voeg luxe meubels/inrichting toe, maak alles volledig afgewerkt. | P33: 46121 | Q33: Mark van Bruggen
A34: FR.34210.34 | C34: 3, 15, 12, 6, 13, 8, 9, 10, 11, 7, 14, 5, 16, 17, 18, 19 | D34: 3, 15, 12, 6, 13, 8, 9, 10, 11, 7, 14, 5, 16, 17, 18, 19 | I34: {=SUMPRODUCT((B34:H34<>"")*1+(LEN(B34:H34)-LEN(SUBSTITUTE(B34:H34,",",""))))} -> 32 | J34: Jill | K34: 46127 | L34: Approved | M34: High | N34: 46134 | O34: Kun je foto 69 de tafel dekken? | P34: 46127 | Q34: Jacqueline Dubois
A35: AT.6341.01 | B35: 4, 6 | I35: 3 | J35: Jill | K35: 46128 | L35: Approved | M35: High | N35: 46134 | P35: 46128 | Q35: Daniel Hell
A36: AT.6370.27 | G36: 23, 24, 25 | I36: {=SUMPRODUCT((B36:H36<>"")*1+(LEN(B36:H36)-LEN(SUBSTITUTE(B36:H36,",",""))))} -> 3 | J36: Jill | K36: 46133 | L36: Approved | M36: High | N36: 46136 | O36: Tandenborstel verwijderen -> tandenborstel alleen weghalen lukte niet dus ik heb dat hele ding weggehaalt. | P36: 46133 | Q36: Georg Stiegler
A37: AT.5531.03 | G37: 64 | I37: {=SUMPRODUCT((B37:H37<>"")*1+(LEN(B37:H37)-LEN(SUBSTITUTE(B37:H37,",",""))))} -> 1 | J37: Jill | K37: 46133 | L37: Approved | M37: High | N37: 46136 | O37: Dozen verwijderen | P37: 46133 | Q37: Ilse Heijnen
A38: NL.4491.02 | G38: 1, 2, 5, 4, 6, 7, 3, 15, 17 | I38: {=SUMPRODUCT((B38:H38<>"")*1+(LEN(B38:H38)-LEN(SUBSTITUTE(B38:H38,",",""))))} -> 9 | J38: Jill | K38: 46146 | L38: Approved | M38: High | N38: 46158 | O38: verwijder alle vermeldingen van ''Zilt'' in foto's | P38: 46146 | Q38: Verhuur Nederland
A39: AT.8953.32 | B39: 2, 23, 24, 25, 37 | I39: {=SUMPRODUCT((B39:H39<>"")*1+(LEN(B39:H39)-LEN(SUBSTITUTE(B39:H39,",",""))))} -> 5 | J39: Jill | K39: 46121 | L39: Approved | M39: Medium | N39: 46148 | Q39: Ilse Heijnen
A40: AT.5531.14 | B40: 82, 83, 84 | I40: {=SUMPRODUCT((B40:H40<>"")*1+(LEN(B40:H40)-LEN(SUBSTITUTE(B40:H40,",",""))))} -> 3 | J40: Jill | K40: 46146 | L40: Approved | M40: Medium | N40: 46148 | Q40: Ilse Heijnen
...

Sheet Work tracker_OLD
A1: AI PHOTO TRACKER
A2: 📊 New: | B2: =COUNTIF(G5:G200,"New") -> 24 | C2: In process: | D2: =COUNTIF(G5:G200,"In process") -> 0 | E2: QC: | F2: =COUNTIF(G5:G200,"QC") -> 0 | G2: Approved: | H2: =COUNTIF(G5:G200,"Approved") -> 0 | I2: Denied: | J2: =COUNTIF(G5:G200,"Denied") -> 0
A3: 🔗 ARES | B3: 🔗 NanoBanana | C3: · | D3: 🔗 Canva | E3: · | F3: 🔗 Tutorial
A4: Acco ID | B4: Count | C4: Photo no. | D4: Editing goal | E4: Assigned to | F4: Date assigned | G4: Status | H4: Priority | I4: Date completed | J4: Notes QC
A5: AT.5771.18 | B5: 13 | D5: Sfeer verbeteren | E5: To be assigned | F5: 46097 | G5: New | H5: Low
A6: AT.5771.17 | B6: 13 | D6: Sfeer verbeteren | E6: To be assigned | F6: 46097 | G6: New | H6: Low
A7: DE.72178.01 | B7: 18 | D7: Sfeer verbeteren | E7: To be assigned | F7: 46097 | G7: New | H7: Low
A8: DE.06493.08 | B8: 17 | D8: Sfeer verbeteren | E8: To be assigned | F8: 46097 | G8: New | H8: Low
A9: AT.5771.19 + 20 + 21 + 22 | B9: 12 | D9: Zomer → winter | E9: To be assigned | F9: 46097 | G9: New | H9: Low
A10: AT.6391.06 + 07 + 08 | B10: 2 | D10: Zomer → winter | E10: To be assigned | F10: 46097 | G10: New | H10: Low
A11: AT.6235.02 + 04 + 05 + 09 +10 + 11 | B11: 3 | D11: Zomer → winter | E11: To be assigned | F11: 46097 | G11: New | H11: Low
A12: AT.6365.46+47+48+49+50 | B12: 3 | E12: To be assigned | F12: 46097 | G12: New | H12: Low
A13: AT.6361.82 + 83 | B13: 4 | D13: Zomer → winter | E13: To be assigned | F13: 46097 | G13: New | H13: Low
A14: AT.6364.53 | B14: 3 | D14: Zomer → winter | F14: 46097 | G14: New | H14: Medium
A15: AT.6335.01 | B15: 2 | F15: 46097 | G15: New | H15: Medium
A16: AT.6341.01 | B16: 3 | D16: Zomer → winter | F16: 46097 | G16: New | H16: Medium
A17: AT.6370.09 | B17: 3 | D17: Zomer → winter | F17: 46097 | G17: New | H17: Medium
A18: AT.9971.09 | B18: 3 | D18: Zomer → winter | F18: 46097 | G18: New | H18: Medium
A19: AT.9971.12 | B19: 3 | D19: Zomer → winter | F19: 46097 | G19: New | H19: Medium
A20: AT.9971.13 | B20: 3 | D20: Zomer → winter | F20: 46097 | G20: New | H20: Medium
A21: AT.9971.14 | B21: 3 | D21: Zomer → winter | F21: 46097 | G21: New | H21: Medium
A22: AT.6300.09 | B22: 4 | F22: 46097 | G22: New | H22: Medium
A23: AT.6292.04 | B23: 4 | D23: Zomer → winter | F23: 46097 | G23: New | H23: Medium
A24: AT.6336.01 | B24: 3 | D24: Zomer → winter | F24: 46097 | G24: New | H24: Medium
A25: AT.5531.07 | B25: 6 | D25: Zomer → winter | F25: 46097 | G25: New | H25: Medium
A26: AT.8953.10 | B26: 1 | D26: Zomer → winter | F26: 46097 | G26: New | H26: Medium
A27: AT.8953.31 | B27: 1 | D27: Zomer → winter | F27: 46097 | G27: New | H27: Medium
A28: AT.8953.47 | B28: 1 | D28: Zomer → winter | F28: 46097 | G28: New | H28: Medium

Sheet Legenda
A1: Legenda
A3: STATUS
A4: New | B4: Foto is aangemeld, nog niet opgepakt
A5: In process | B5: Editor is actief bezig met de foto
A6: QC | B6: Bewerking klaar, wacht op kwaliteitscontrole door coördinator
A7: Approved | B7: QC geslaagd, foto gepubliceerd in ARES
A8: Denied | B8: Foto voldoet niet, editor moet opnieuw bewerken
A11: EDITING GOAL
A12: Summer → winter | B12: Foto is gemaakt in de zomer, maar winterversie is nodig voor de listing
A13: Improve lighting | B13: Foto is te donker, te licht of heeft storende schaduwen
A14: Improve ambiance | B14: Foto is technisch goed maar voelt koud, leeg of onuitnodigend aan
A15: Replace sky | B15: Lucht is bewolkt, grauw of saai
A16: Make beds | B16: Bed ziet er rommelig of onopgemaakt uit
A17: Remove object | B17: Storend element in beeld zoals een auto, vuilnisbak, persoon etc.
A18: Improve summer | B18: Foto is gemaakt in de zomer maar oogt dof, vlak of weinig uitnodigend
A21: SELECTIE
A22: Kies maximaal 3-5 foto’s per woning
A23: Prioriteit 1: potentiële hero images: buitenkant, zwembad, terras, spectaculair interieur. Dit levert het meeste rendement. Prioriteit 2: USP's of bijzondere ruimtes die technisch tegenvallen: slechte belichting, vlakke sfeer, rommelig etc. De ruimte zelf moet interessant genoeg zijn. Sla gewone/saaie ruimtes met slechte foto's over. We kunnen foto's verbeteren met AI, niet de ruimte zelf.

Sheet Dashboard
R1: Ilse Heijnen | S1: =COUNTIFS(Tracker!Q5:Q356,R1,Tracker!L5:L356,"<>") -> 52 | T1: =RANK(S1,$S$1:$S$17,0)+COUNTIF($S$1:$S1,S1)-1 -> 1
B2: AI PHOTO EDITING - DASHBOARD | R2: Carl-Peter Echtermeijer | S2: =COUNTIFS(Tracker!Q5:Q356,R2,Tracker!L5:L356,"<>") -> 26 | T2: =RANK(S2,$S$1:$S$17,0)+COUNTIF($S$1:$S2,S2)-1 -> 3
B3: Real-time overview of all photo editing assignments | R3: Karin Wagemans | S3: =COUNTIFS(Tracker!Q5:Q356,R3,Tracker!L5:L356,"<>") -> 4 | T3: =RANK(S3,$S$1:$S$17,0)+COUNTIF($S$1:$S3,S3)-1 -> 9
R4: Georg Stiegler | S4: =COUNTIFS(Tracker!Q5:Q356,R4,Tracker!L5:L356,"<>") -> 30 | T4: =RANK(S4,$S$1:$S$17,0)+COUNTIF($S$1:$S4,S4)-1 -> 2
R5: Wim Westerdijk | S5: =COUNTIFS(Tracker!Q5:Q356,R5,Tracker!L5:L356,"<>") -> 11 | T5: =RANK(S5,$S$1:$S$17,0)+COUNTIF($S$1:$S5,S5)-1 -> 4
B6: TOTAL ASSIGNMENTS | E6: APPROVAL RATE | H6: AVG. TURNAROUND | K6: TOTAL PHOTOS | R6: Brigitte Bruijnse | S6: =COUNTIFS(Tracker!Q5:Q356,R6,Tracker!L5:L356,"<>") -> 0 | T6: =RANK(S6,$S$1:$S$17,0)+COUNTIF($S$1:$S6,S6)-1 -> 14
B7: =COUNTIFS(Tracker!A5:A356,"<>",Tracker!L5:L356,"<>") -> 199 | E7: =IFERROR(COUNTIF(Tracker!L5:L356,"Approved")/COUNTIFS(Tracker!L5:L356,"<>",Tracker!L5:L356,"<>New",Tracker!L5:L356,"<>In process"),0) -> 0.93333333 | H7: {=IFERROR(ROUND(SUMPRODUCT((Tracker!N5:N356>0)*(Tracker!P5:P356>0)*(Tracker!L5:L356<>"")*(Tracker!N5:N356-Tracker!P5:P356))/SUMPRODUCT((Tracker!N5:N356>0)*(Tracker!P5:P356>0)*(Tracker!L5:L356<>"")*1),1),"-")} -> 8 | K7: =SUMIF(Tracker!L5:L356,"<>",Tracker!I5:I356) -> 944 | R7: Michael Fritz | S7: =COUNTIFS(Tracker!Q5:Q356,R7,Tracker!L5:L356,"<>") -> 0 | T7: =RANK(S7,$S$1:$S$17,0)+COUNTIF($S$1:$S7,S7)-1 -> 15
B8: ="of which "&COUNTIF(Tracker!L5:L356,"New")&" new" -> of which 63 new | E8: =COUNTIF(Tracker!L5:L356,"Approved")&" approved / "&COUNTIF(Tracker!L5:L356,"Denied")&" denied" -> 126 approved / 1 denied | H8: days (requested → completed) | K8: ="avg. "&FIXED(IFERROR(SUMIF(Tracker!L5:L356,"<>",Tracker!I5:I356)/COUNTIFS(Tracker!A5:A356,"<>",Tracker!L5:L356,"<>"),0),1)&" per property" -> avg. 4,7 per property | R8: Sabine van Tuijn | S8: =COUNTIFS(Tracker!Q5:Q356,R8,Tracker!L5:L356,"<>") -> 11 | T8: =RANK(S8,$S$1:$S$17,0)+COUNTIF($S$1:$S8,S8)-1 -> 5
R9: Martijn de Jongh | S9: =COUNTIFS(Tracker!Q5:Q356,R9,Tracker!L5:L356,"<>") -> 0 | T9: =RANK(S9,$S$1:$S$17,0)+COUNTIF($S$1:$S9,S9)-1 -> 16
B10: STATUS OVERVIEW | H10: PRIORITY & BACKLOG | R10: Monique van der Stap | S10: =COUNTIFS(Tracker!Q5:Q356,R10,Tracker!L5:L356,"<>") -> 4 | T10: =RANK(S10,$S$1:$S$17,0)+COUNTIF($S$1:$S10,S10)-1 -> 10
B11: Status | C11: Count | E11: % of total | H11: Priority | I11: Count | K11: % of total | R11: Mark van Bruggen | S11: =COUNTIFS(Tracker!Q5:Q356,R11,Tracker!L5:L356,"<>") -> 3 | T11: =RANK(S11,$S$1:$S$17,0)+COUNTIF($S$1:$S11,S11)-1 -> 11
B12: 🟢 Approved | C12: =COUNTIF(Tracker!L5:L356,"Approved") -> 126 | E12: =IFERROR(C12/SUM($C$12:$C$16),0) -> 0.63636364 | F12: =REPT("█",ROUND(E12*20,0))&REPT("░",20-ROUND(E12*20,0)) -> █████████████░░░░░░░ | H12: 🔴 High | I12: =COUNTIFS(Tracker!M5:M356,"High",Tracker!L5:L356,"<>") -> 98 | K12: =IFERROR(I12/SUM($I$12:$I$14),0) -> 0.49246231 | L12: =REPT("█",ROUND(K12*20,0))&REPT("░",20-ROUND(K12*20,0)) -> ██████████░░░░░░░░░░ | R12: Phyllis Muschalik | S12: =COUNTIFS(Tracker!Q5:Q356,R12,Tracker!L5:L356,"<>") -> 9 | T12: =RANK(S12,$S$1:$S$17,0)+COUNTIF($S$1:$S12,S12)-1 -> 6
B13: 🔵 In process | C13: =COUNTIF(Tracker!L5:L356,"In process") -> 1 | E13: =IFERROR(C13/SUM($C$12:$C$16),0) -> 0.0050505051 | F13: =REPT("█",ROUND(E13*20,0))&REPT("░",20-ROUND(E13*20,0)) -> ░░░░░░░░░░░░░░░░░░░░ | H13: 🟡 Medium | I13: =COUNTIFS(Tracker!M5:M356,"Medium",Tracker!L5:L356,"<>") -> 33 | K13: =IFERROR(I13/SUM($I$12:$I$14),0) -> 0.16582915 | L13: =REPT("█",ROUND(K13*20,0))&REPT("░",20-ROUND(K13*20,0)) -> ███░░░░░░░░░░░░░░░░░ | R13: Daniel Hell | S13: =COUNTIFS(Tracker!Q5:Q356,R13,Tracker!L5:L356,"<>") -> 6 | T13: =RANK(S13,$S$1:$S$17,0)+COUNTIF($S$1:$S13,S13)-1 -> 8
B14: 🟡 QC | C14: =COUNTIF(Tracker!L5:L356,"QC") -> 7 | E14: =IFERROR(C14/SUM($C$12:$C$16),0) -> 0.035353535 | F14: =REPT("█",ROUND(E14*20,0))&REPT("░",20-ROUND(E14*20,0)) -> █░░░░░░░░░░░░░░░░░░░ | H14: 🟢 Low | I14: =COUNTIFS(Tracker!M5:M356,"Low",Tracker!L5:L356,"<>") -> 68 | K14: =IFERROR(I14/SUM($I$12:$I$14),0) -> 0.34170854 | L14: =REPT("█",ROUND(K14*20,0))&REPT("░",20-ROUND(K14*20,0)) -> ███████░░░░░░░░░░░░░ | R14: Koen van Tuijn | S14: =COUNTIFS(Tracker!Q5:Q356,R14,Tracker!L5:L356,"<>") -> 1 | T14: =RANK(S14,$S$1:$S$17,0)+COUNTIF($S$1:$S14,S14)-1 -> 12
B15: 🔴 Denied | C15: =COUNTIF(Tracker!L5:L356,"Denied") -> 1 | E15: =IFERROR(C15/SUM($C$12:$C$16),0) -> 0.0050505051 | F15: =REPT("█",ROUND(E15*20,0))&REPT("░",20-ROUND(E15*20,0)) -> ░░░░░░░░░░░░░░░░░░░░ | H15: 📦 Unassigned | I15: =COUNTIFS(Tracker!J5:J356,"",Tracker!L5:L356,"<>") -> 34 | K15: =IFERROR(I15/COUNTIFS(Tracker!A5:A356,"<>",Tracker!L5:L356,"<>"),0) -> 0.17085427 | L15: =REPT("█",ROUND(K15*20,0))&REPT("░",20-ROUND(K15*20,0)) -> ███░░░░░░░░░░░░░░░░░ | R15: Matthias Hauer | S15: =COUNTIFS(Tracker!Q5:Q356,R15,Tracker!L5:L356,"<>") -> 8 | T15: =RANK(S15,$S$1:$S$17,0)+COUNTIF($S$1:$S15,S15)-1 -> 7
B16: ⚪ New | C16: =COUNTIF(Tracker!L5:L356,"New") -> 63 | E16: =IFERROR(C16/SUM($C$12:$C$16),0) -> 0.31818182 | F16: =REPT("█",ROUND(E16*20,0))&REPT("░",20-ROUND(E16*20,0)) -> ██████░░░░░░░░░░░░░░ | R16: Jacqueline Kunst-Dubois | S16: =COUNTIFS(Tracker!Q5:Q356,R16,Tracker!L5:L356,"<>") -> 0 | T16: =RANK(S16,$S$1:$S$17,0)+COUNTIF($S$1:$S16,S16)-1 -> 17
R17: Paula Huizenga | S17: =COUNTIFS(Tracker!Q5:Q356,R17,Tracker!L5:L356,"<>") -> 1 | T17: =RANK(S17,$S$1:$S$17,0)+COUNTIF($S$1:$S17,S17)-1 -> 13
B18: 👤EDITOR PERFORMANCE
B19: Editor | C19: Assigned | E19: Approved | F19: Denied | H19: In process | I19: Approval % | K19: Avg. days | L19: Photos | R19: Status | S19: Aantal
B20: Jill | C20: =COUNTIFS(Tracker!J5:J356,"Jill",Tracker!L5:L356,"<>") -> 77 | E20: =COUNTIFS(Tracker!J5:J356,"Jill",Tracker!L5:L356,"Approved") -> 77 | F20: =COUNTIFS(Tracker!J5:J356,"Jill",Tracker!L5:L356,"Denied") -> 0 | H20: =COUNTIFS(Tracker!J5:J356,"Jill",Tracker!L5:L356,"In process") -> 0 | I20: =IFERROR(E20/(E20+F20),0) -> 1 | K20: {=IFERROR(ROUND(SUMPRODUCT((Tracker!J5:J356="Jill")*(Tracker!L5:L356<>"")*(Tracker!N5:N356>0)*(Tracker!P5:P356>0)*(Tracker!N5:N356-Tracker!P5:P356))/SUMPRODUCT((Tracker!J5:J356="Jill")*(Tracker!L5:L356<>"")*(Tracker!N5:N356>0)*(Tracker!P5:P356>0)*1),1),"-")} -> 8.3 | L20: =SUMIFS(Tracker!I5:I356,Tracker!J5:J356,"Jill",Tracker!L5:L356,"<>") -> 315 | R20: Approved | S20: =C12 -> 126
B21: Wouter | C21: =COUNTIFS(Tracker!J5:J356,"Wouter",Tracker!L5:L356,"<>") -> 4 | E21: =COUNTIFS(Tracker!J5:J356,"Wouter",Tracker!L5:L356,"Approved") -> 4 | F21: =COUNTIFS(Tracker!J5:J356,"Wouter",Tracker!L5:L356,"Denied") -> 0 | H21: =COUNTIFS(Tracker!J5:J356,"Wouter",Tracker!L5:L356,"In process") -> 0 | I21: =IFERROR(E21/(E21+F21),0) -> 1 | K21: {=IFERROR(ROUND(SUMPRODUCT((Tracker!J5:J356="Wouter")*(Tracker!L5:L356<>"")*(Tracker!N5:N356>0)*(Tracker!P5:P356>0)*(Tracker!N5:N356-Tracker!P5:P356))/SUMPRODUCT((Tracker!J5:J356="Wouter")*(Tracker!L5:L356<>"")*(Tracker!N5:N356>0)*(Tracker!P5:P356>0)*1),1),"-")} -> 0.8 | L21: =SUMIFS(Tracker!I5:I356,Tracker!J5:J356,"Wouter",Tracker!L5:L356,"<>") -> 37 | R21: In process | S21: =C13 -> 1
B22: Rosalynn | C22: =COUNTIFS(Tracker!J5:J356,"Rosalynn",Tracker!L5:L356,"<>") -> 54 | E22: =COUNTIFS(Tracker!J5:J356,"Rosalynn",Tracker!L5:L356,"Approved") -> 21 | F22: =COUNTIFS(Tracker!J5:J356,"Rosalynn",Tracker!L5:L356,"Denied") -> 1 | H22: =COUNTIFS(Tracker!J5:J356,"Rosalynn",Tracker!L5:L356,"In process") -> 1 | I22: =IFERROR(E22/(E22+F22),0) -> 0.95454545 | K22: {=IFERROR(ROUND(SUMPRODUCT((Tracker!J5:J356="Rosalynn")*(Tracker!L5:L356<>"")*(Tracker!N5:N356>0)*(Tracker!P5:P356>0)*(Tracker!N5:N356-Tracker!P5:P356))/SUMPRODUCT((Tracker!J5:J356="Rosalynn")*(Tracker!L5:L356<>"")*(Tracker!N5:N356>0)*(Tracker!P5:P356>0)*1),1),"-")} -> 13.5 | L22: =SUMIFS(Tracker!I5:I356,Tracker!J5:J356,"Rosalynn",Tracker!L5:L356,"<>") -> 332 | R22: QC | S22: =C14 -> 7
B23: Kaylee | C23: =COUNTIFS(Tracker!J5:J356,$B23,Tracker!L5:L356,"<>") -> 22 | E23: =COUNTIFS(Tracker!J5:J356,$B23,Tracker!L5:L356,"Approved") -> 16 | F23: =COUNTIFS(Tracker!J5:J356,$B23,Tracker!L5:L356,"Denied") -> 0 | H23: =COUNTIFS(Tracker!J5:J356,$B23,Tracker!L5:L356,"In process") -> 0 | I23: =IFERROR(E23/(E23+F23),0) -> 1 | K23: {=IFERROR(ROUND(SUMPRODUCT((Tracker!J5:J356=$B23)*(Tracker!L5:L356<>"")*(Tracker!N5:N356>0)*(Tracker!P5:P356>0)*(Tracker!N5:N356-Tracker!P5:P356))/SUMPRODUCT((Tracker!J5:J356=$B23)*(Tracker!L5:L356<>"")*(Tracker!N5:N356>0)*(Tracker!P5:P356>0)*1),1),"-")} -> 2.9 | L23: =SUMIFS(Tracker!I5:I356,Tracker!J5:J356,$B23,Tracker!L5:L356,"<>") -> 133
B24: TOTAL | C24: =SUM(C20:C23) -> 157 | E24: =SUM(E20:E23) -> 118 | F24: =SUM(F20:F23) -> 1 | H24: =SUM(H20:H23) -> 1 | I24: =IFERROR(E24/(E24+F24),0) -> 0.99159664 | K24: =H7 -> 8 | L24: =SUM(L20:L23) -> 817 | R24: Denied | S24: =C15 -> 1
R25: New | S25: =C16 -> 63
B26: RENTAL EXPERTS (TOP 10) | H26: EDITING GOALS OVERVIEW
B27: # | C27: Rental Expert | E27: Assignments | F27: % of total | H27: Editing Goal | K27: Count | L27: Percentage | R27: Approved | S27: =C12 -> 126
B28: 1 | C28: =IFERROR(INDEX($R$1:$R$17,MATCH(B28,$T$1:$T$17,0)),"") -> Ilse Heijnen | E28: =IFERROR(INDEX($S$1:$S$17,MATCH(B28,$T$1:$T$17,0)),"") -> 52 | F28: =IFERROR(E28/COUNTIFS(Tracker!A5:A356,"<>",Tracker!L5:L356,"<>"),"") -> 0.26130653 | H28: ❄️ Summer → Winter | K28: =COUNTIFS(Tracker!B5:B356,"<>",Tracker!L5:L356,"<>") -> 48 | L28: =REPT("█",IFERROR(ROUND(K28/MAX($K$28:$K$34)*15,0),0)) -> ██████████ | R28: In process | S28: =C13 -> 1
B29: 2 | C29: =IFERROR(INDEX($R$1:$R$17,MATCH(B29,$T$1:$T$17,0)),"") -> Georg Stiegler | E29: =IFERROR(INDEX($S$1:$S$17,MATCH(B29,$T$1:$T$17,0)),"") -> 30 | F29: =IFERROR(E29/COUNTIFS(Tracker!A5:A356,"<>",Tracker!L5:L356,"<>"),"") -> 0.15075377 | H29: 💡 Improve lighting | K29: =COUNTIFS(Tracker!C5:C356,"<>",Tracker!L5:L356,"<>") -> 51 | L29: =REPT("█",IFERROR(ROUND(K29/MAX($K$28:$K$34)*15,0),0)) -> ███████████ | R29: QC | S29: =C14 -> 7
B30: 3 | C30: =IFERROR(INDEX($R$1:$R$17,MATCH(B30,$T$1:$T$17,0)),"") -> Carl-Peter Echtermeijer | E30: =IFERROR(INDEX($S$1:$S$17,MATCH(B30,$T$1:$T$17,0)),"") -> 26 | F30: =IFERROR(E30/COUNTIFS(Tracker!A5:A356,"<>",Tracker!L5:L356,"<>"),"") -> 0.13065327 | H30: ✨ Improve ambiance | K30: =COUNTIFS(Tracker!D5:D356,"<>",Tracker!L5:L356,"<>") -> 38 | L30: =REPT("█",IFERROR(ROUND(K30/MAX($K$28:$K$34)*15,0),0)) -> ████████ | R30: Denied | S30: =C15 -> 1
B31: 4 | C31: =IFERROR(INDEX($R$1:$R$17,MATCH(B31,$T$1:$T$17,0)),"") -> Wim Westerdijk | E31: =IFERROR(INDEX($S$1:$S$17,MATCH(B31,$T$1:$T$17,0)),"") -> 11 | F31: =IFERROR(E31/COUNTIFS(Tracker!A5:A356,"<>",Tracker!L5:L356,"<>"),"") -> 0.055276382 | H31: 🌤️ Replace sky | K31: =COUNTIFS(Tracker!E5:E356,"<>",Tracker!L5:L356,"<>") -> 34 | L31: =REPT("█",IFERROR(ROUND(K31/MAX($K$28:$K$34)*15,0),0)) -> ███████
B32: 5 | C32: =IFERROR(INDEX($R$1:$R$17,MATCH(B32,$T$1:$T$17,0)),"") -> Sabine van Tuijn | E32: =IFERROR(INDEX($S$1:$S$17,MATCH(B32,$T$1:$T$17,0)),"") -> 11 | F32: =IFERROR(E32/COUNTIFS(Tracker!A5:A356,"<>",Tracker!L5:L356,"<>"),"") -> 0.055276382 | H32: 🛏️ Make beds | K32: =COUNTIFS(Tracker!F5:F356,"<>",Tracker!L5:L356,"<>") -> 2 | L32: =REPT("█",IFERROR(ROUND(K32/MAX($K$28:$K$34)*15,0),0)) | R32: New | S32: =C16 -> 63
B33: 6 | C33: =IFERROR(INDEX($R$1:$R$17,MATCH(B33,$T$1:$T$17,0)),"") -> Phyllis Muschalik | E33: =IFERROR(INDEX($S$1:$S$17,MATCH(B33,$T$1:$T$17,0)),"") -> 9 | F33: =IFERROR(E33/COUNTIFS(Tracker!A5:A356,"<>",Tracker!L5:L356,"<>"),"") -> 0.045226131 | H33: 🗑️ Remove object | K33: =COUNTIFS(Tracker!G5:G356,"<>",Tracker!L5:L356,"<>") -> 32 | L33: =REPT("█",IFERROR(ROUND(K33/MAX($K$28:$K$34)*15,0),0)) -> ███████
B34: 7 | C34: =IFERROR(INDEX($R$1:$R$17,MATCH(B34,$T$1:$T$17,0)),"") -> Matthias Hauer | E34: =IFERROR(INDEX($S$1:$S$17,MATCH(B34,$T$1:$T$17,0)),"") -> 8 | F34: =IFERROR(E34/COUNTIFS(Tracker!A5:A356,"<>",Tracker!L5:L356,"<>"),"") -> 0.040201005 | H34: ☀️ Improve summer | K34: =COUNTIFS(Tracker!H5:H356,"<>",Tracker!L5:L356,"<>") -> 71 | L34: =REPT("█",IFERROR(ROUND(K34/MAX($K$28:$K$34)*15,0),0)) -> ███████████████ | R34: Summer→Winter | S34: =K28 -> 48
B35: 8 | C35: =IFERROR(INDEX($R$1:$R$17,MATCH(B35,$T$1:$T$17,0)),"") -> Daniel Hell | E35: =IFERROR(INDEX($S$1:$S$17,MATCH(B35,$T$1:$T$17,0)),"") -> 6 | F35: =IFERROR(E35/COUNTIFS(Tracker!A5:A356,"<>",Tracker!L5:L356,"<>"),"") -> 0.030150754 | R35: Lighting | S35: =K29 -> 51
B36: 9 | C36: =IFERROR(INDEX($R$1:$R$17,MATCH(B36,$T$1:$T$17,0)),"") -> Karin Wagemans | E36: =IFERROR(INDEX($S$1:$S$17,MATCH(B36,$T$1:$T$17,0)),"") -> 4 | F36: =IFERROR(E36/COUNTIFS(Tracker!A5:A356,"<>",Tracker!L5:L356,"<>"),"") -> 0.020100503 | R36: Ambiance | S36: =K30 -> 38
B37: 10 | C37: =IFERROR(INDEX($R$1:$R$17,MATCH(B37,$T$1:$T$17,0)),"") -> Monique van der Stap | E37: =IFERROR(INDEX($S$1:$S$17,MATCH(B37,$T$1:$T$17,0)),"") -> 4 | F37: =IFERROR(E37/COUNTIFS(Tracker!A5:A356,"<>",Tracker!L5:L356,"<>"),"") -> 0.020100503 | R37: Replace sky | S37: =K31 -> 34
R38: Make beds | S38: =K32 -> 2
R39: Remove object | S39: =K33 -> 32
B40: STATUS DISTRIBUTION | H40: EDITING GOALS DISTRIBUTION | R40: Improve summer | S40: =K34 -> 71
...
